2023-05-23 23:03:36,299 INFO build_combined_normalized_csv(30) 202 sources selected to process
2023-05-23 23:03:40,809 INFO build_combined_normalized_csv(47) Source S-1 extract with 195 rows::: ILO_Extractor
2023-05-23 23:03:44,769 INFO build_combined_normalized_csv(47) Source S-2 extract with 195 rows::: ILO_Extractor
2023-05-23 23:03:44,994 INFO build_combined_normalized_csv(47) Source S-3 extract with 195 rows::: UnTreaties
2023-05-23 23:03:45,157 INFO build_combined_normalized_csv(47) Source S-4 extract with 195 rows::: UnTreaties
2023-05-23 23:03:49,658 INFO build_combined_normalized_csv(47) Source S-5 extract with 195 rows::: ILO_Extractor
2023-05-23 23:03:53,524 INFO build_combined_normalized_csv(47) Source S-6 extract with 195 rows::: ILO_Extractor
2023-05-23 23:03:56,255 INFO build_combined_normalized_csv(47) Source S-7 extract with 195 rows::: ILO_Extractor
2023-05-23 23:03:56,691 INFO build_combined_normalized_csv(47) Source S-15 extract with 954 rows::: DefaultJsonExtractor
2023-05-23 23:03:57,076 INFO build_combined_normalized_csv(47) Source S-16 extract with 954 rows::: DefaultJsonExtractor
2023-05-23 23:03:57,256 INFO build_combined_normalized_csv(47) Source S-17 extract with 381 rows::: DefaultJsonExtractor
2023-05-23 23:04:00,287 INFO build_combined_normalized_csv(47) Source S-18 extract with 195 rows::: ILO_Extractor
2023-05-23 23:04:02,847 INFO build_combined_normalized_csv(47) Source S-19 extract with 195 rows::: ILO_Extractor
2023-05-23 23:04:05,621 INFO build_combined_normalized_csv(47) Source S-20 extract with 195 rows::: ILO_Extractor
2023-05-23 23:04:08,458 INFO build_combined_normalized_csv(47) Source S-21 extract with 195 rows::: ILO_Extractor
2023-05-23 23:04:12,333 INFO build_combined_normalized_csv(47) Source S-22 extract with 195 rows::: ILO_Extractor
2023-05-23 23:04:15,773 INFO build_combined_normalized_csv(47) Source S-23 extract with 195 rows::: ILO_Extractor
2023-05-23 23:04:15,971 INFO build_combined_normalized_csv(47) Source S-24 extract with 195 rows::: UnTreaties
2023-05-23 23:04:19,781 INFO build_combined_normalized_csv(47) Source S-25 extract with 195 rows::: ILO_Extractor
2023-05-23 23:04:23,627 INFO build_combined_normalized_csv(47) Source S-26 extract with 195 rows::: ILO_Extractor
2023-05-23 23:04:27,576 INFO build_combined_normalized_csv(47) Source S-27 extract with 195 rows::: ILO_Extractor
2023-05-23 23:04:30,585 INFO build_combined_normalized_csv(47) Source S-28 extract with 195 rows::: ILO_Extractor
2023-05-23 23:04:30,800 INFO build_combined_normalized_csv(47) Source S-43 extract with 541 rows::: DefaultCSVExtractor
2023-05-23 23:04:31,024 INFO build_combined_normalized_csv(47) Source S-221 extract with 195 rows::: HumanEnteredBlueprintIndicatorBuilder
2023-05-23 23:04:31,195 INFO build_combined_normalized_csv(47) Source S-46 extract with 379 rows::: DefaultCSVExtractor
2023-05-23 23:04:31,326 INFO build_combined_normalized_csv(47) Source S-47 extract with 409 rows::: DefaultCSVExtractor
2023-05-23 23:04:34,054 INFO build_combined_normalized_csv(47) Source S-48 extract with 195 rows::: ILO_Extractor
2023-05-23 23:04:36,876 INFO build_combined_normalized_csv(47) Source S-49 extract with 195 rows::: ILO_Extractor
2023-05-23 23:04:37,228 INFO build_combined_normalized_csv(47) Source S-50 extract with 195 rows::: UnTreaties
2023-05-23 23:04:37,414 INFO build_combined_normalized_csv(47) Source S-52 extract with 195 rows::: DefaultJsonExtractor
2023-05-23 23:04:37,787 INFO build_combined_normalized_csv(47) Source S-53 extract with 970 rows::: DefaultJsonExtractor
2023-05-23 23:04:37,911 INFO build_combined_normalized_csv(47) Source S-62 extract with 195 rows::: DefaultJsonExtractor
2023-05-23 23:04:38,081 INFO build_combined_normalized_csv(47) Source S-63 extract with 312 rows::: DefaultJsonExtractor
2023-05-23 23:04:38,222 INFO build_combined_normalized_csv(47) Source S-65 extract with 312 rows::: DefaultJsonExtractor
2023-05-23 23:04:38,408 INFO build_combined_normalized_csv(47) Source S-66 extract with 265 rows::: DefaultJsonExtractor
2023-05-23 23:04:38,508 INFO build_combined_normalized_csv(47) Source S-67 extract with 265 rows::: DefaultJsonExtractor
2023-05-23 23:04:38,577 INFO build_combined_normalized_csv(47) Source S-68 extract with 195 rows::: DefaultCSVExtractor
2023-05-23 23:04:38,659 INFO build_combined_normalized_csv(47) Source S-69 extract with 195 rows::: DefaultCSVExtractor
2023-05-23 23:04:38,729 INFO build_combined_normalized_csv(47) Source S-70 extract with 195 rows::: DefaultCSVExtractor
2023-05-23 23:04:38,799 INFO build_combined_normalized_csv(47) Source S-71 extract with 195 rows::: DefaultCSVExtractor
2023-05-23 23:04:38,973 INFO build_combined_normalized_csv(47) Source S-72 extract with 195 rows::: UnTreaties
2023-05-23 23:04:39,041 INFO build_combined_normalized_csv(47) Source S-74 extract with 195 rows::: DefaultCSVExtractor
2023-05-23 23:04:39,117 INFO build_combined_normalized_csv(47) Source S-76 extract with 195 rows::: DefaultCSVExtractor
2023-05-23 23:04:39,193 INFO build_combined_normalized_csv(47) Source S-77 extract with 195 rows::: DefaultCSVExtractor
2023-05-23 23:04:39,245 INFO build_combined_normalized_csv(47) Source S-78 extract with 579 rows::: DefaultCSVExtractor
2023-05-23 23:04:39,297 INFO build_combined_normalized_csv(47) Source S-79 extract with 579 rows::: DefaultCSVExtractor
2023-05-23 23:04:39,363 INFO build_combined_normalized_csv(47) Source S-80 extract with 195 rows::: DefaultCSVExtractor
2023-05-23 23:04:39,452 INFO build_combined_normalized_csv(47) Source S-81 extract with 195 rows::: HumanEnteredBlueprintIndicatorBuilder
2023-05-23 23:04:39,546 INFO build_combined_normalized_csv(47) Source S-82 extract with 461 rows::: DefaultCSVExtractor
2023-05-23 23:04:39,636 INFO build_combined_normalized_csv(47) Source S-83 extract with 331 rows::: DefaultCSVExtractor
2023-05-23 23:04:39,817 INFO build_combined_normalized_csv(47) Source S-84 extract with 195 rows::: DefaultCSVExtractor
2023-05-23 23:04:40,900 INFO build_combined_normalized_csv(47) Source S-85 extract with 1699 rows::: DefaultCSVExtractor
2023-05-23 23:04:40,999 INFO build_combined_normalized_csv(47) Source S-86 extract with 195 rows::: GlobalHealthObservatory
2023-05-23 23:04:41,069 INFO build_combined_normalized_csv(47) Source S-87 extract with 195 rows::: GlobalHealthObservatory
2023-05-23 23:04:41,221 INFO build_combined_normalized_csv(47) Source S-88 extract with 195 rows::: UnTreaties
2023-05-23 23:04:41,437 INFO build_combined_normalized_csv(47) Source S-89 extract with 195 rows::: HumanEnteredBlueprintIndicatorBuilder
2023-05-23 23:04:41,615 INFO build_combined_normalized_csv(47) Source S-90 extract with 195 rows::: HumanEnteredBlueprintIndicatorBuilder
2023-05-23 23:04:41,851 INFO build_combined_normalized_csv(47) Source S-91 extract with 561 rows::: DefaultCSVExtractor
2023-05-23 23:04:42,100 INFO build_combined_normalized_csv(47) Source S-92 extract with 195 rows::: UnTreaties
2023-05-23 23:04:42,213 INFO build_combined_normalized_csv(47) Source S-93 extract with 195 rows::: HumanEnteredBlueprintIndicatorBuilder
2023-05-23 23:04:42,378 INFO build_combined_normalized_csv(47) Source S-98 extract with 195 rows::: HumanEnteredBlueprintIndicatorBuilder
2023-05-23 23:04:42,531 INFO build_combined_normalized_csv(47) Source S-99 extract with 195 rows::: HumanEnteredBlueprintIndicatorBuilder
2023-05-23 23:04:42,532 WARNING build_combined_normalized_csv(54) Source S-100 failed to extract cause of: [Errno 2] No such file or directory: 'config/2023/in/data/staging/S-100.xlsx'
Traceback (most recent call last):
  File "/home/lasse/Development/crba-allinone/etl/source_adapter/abstract.py", line 90, in build
    self.download().transform()
  File "/home/lasse/Development/crba-allinone/etl/source_adapter/abstract.py", line 109, in download
    self.dataframe = self._download()
  File "/home/lasse/Development/crba-allinone/etl/source_adapter/manual.py", line 28, in _download
    self.dataframe = pd.read_excel(
  File "/home/lasse/.cache/pypoetry/virtualenvs/crba-project-5qZtH06h-py3.10/lib/python3.10/site-packages/pandas/util/_decorators.py", line 211, in wrapper
    return func(*args, **kwargs)
  File "/home/lasse/.cache/pypoetry/virtualenvs/crba-project-5qZtH06h-py3.10/lib/python3.10/site-packages/pandas/util/_decorators.py", line 331, in wrapper
    return func(*args, **kwargs)
  File "/home/lasse/.cache/pypoetry/virtualenvs/crba-project-5qZtH06h-py3.10/lib/python3.10/site-packages/pandas/io/excel/_base.py", line 482, in read_excel
    io = ExcelFile(io, storage_options=storage_options, engine=engine)
  File "/home/lasse/.cache/pypoetry/virtualenvs/crba-project-5qZtH06h-py3.10/lib/python3.10/site-packages/pandas/io/excel/_base.py", line 1652, in __init__
    ext = inspect_excel_format(
  File "/home/lasse/.cache/pypoetry/virtualenvs/crba-project-5qZtH06h-py3.10/lib/python3.10/site-packages/pandas/io/excel/_base.py", line 1525, in inspect_excel_format
    with get_handle(
  File "/home/lasse/.cache/pypoetry/virtualenvs/crba-project-5qZtH06h-py3.10/lib/python3.10/site-packages/pandas/io/common.py", line 865, in get_handle
    handle = open(handle, ioargs.mode)
FileNotFoundError: [Errno 2] No such file or directory: 'config/2023/in/data/staging/S-100.xlsx'

The above exception was the direct cause of the following exception:

Traceback (most recent call last):
  File "/home/lasse/Development/crba-allinone/etl/run.py", line 44, in build_combined_normalized_csv
    extractor.build()
  File "/home/lasse/Development/crba-allinone/etl/source_adapter/abstract.py", line 100, in build
    raise ExtractionError(
etl.source_adapter.abstract.ExtractionError: Source S-100 failed to extract cause of: [Errno 2] No such file or directory: 'config/2023/in/data/staging/S-100.xlsx'
2023-05-23 23:04:42,677 INFO build_combined_normalized_csv(47) Source S-102 extract with 207 rows::: DefaultJsonExtractor
2023-05-23 23:04:42,841 INFO build_combined_normalized_csv(47) Source S-103 extract with 444 rows::: DefaultCSVExtractor
2023-05-23 23:04:43,017 INFO build_combined_normalized_csv(47) Source S-108 extract with 195 rows::: DefaultJsonExtractor
2023-05-23 23:04:43,194 INFO build_combined_normalized_csv(47) Source S-109 extract with 195 rows::: DefaultJsonExtractor
2023-05-23 23:04:43,455 INFO build_combined_normalized_csv(47) Source S-110 extract with 195 rows::: DefaultJsonExtractor
2023-05-23 23:04:43,654 INFO build_combined_normalized_csv(47) Source S-111 extract with 195 rows::: DefaultJsonExtractor
2023-05-23 23:04:43,829 INFO build_combined_normalized_csv(47) Source S-112 extract with 195 rows::: DefaultJsonExtractor
2023-05-23 23:04:44,012 INFO build_combined_normalized_csv(47) Source S-113 extract with 195 rows::: DefaultJsonExtractor
2023-05-23 23:04:44,507 INFO build_combined_normalized_csv(47) Source S-114 extract with 195 rows::: CRIN_Treaties
2023-05-23 23:04:44,550 INFO build_combined_normalized_csv(47) Source S-119 extract with 195 rows::: DefaultCSVExtractor
2023-05-23 23:04:44,623 INFO build_combined_normalized_csv(47) Source S-120 extract with 195 rows::: DefaultCSVExtractor
2023-05-23 23:04:44,765 INFO build_combined_normalized_csv(47) Source S-121 extract with 195 rows::: HumanEnteredBlueprintIndicatorBuilder
2023-05-23 23:04:44,875 WARNING build_combined_normalized_csv(54) Source S-122 failed to extract cause of: Unable to parse string "VALUE WITHOUT MAPPING - PLEASE MAP" at position 0
Traceback (most recent call last):
  File "pandas/_libs/lib.pyx", line 2369, in pandas._libs.lib.maybe_convert_numeric
ValueError: Unable to parse string "VALUE WITHOUT MAPPING - PLEASE MAP"

During handling of the above exception, another exception occurred:

Traceback (most recent call last):
  File "/home/lasse/Development/crba-allinone/etl/source_adapter/abstract.py", line 90, in build
    self.download().transform()
  File "/home/lasse/Development/crba-allinone/etl/source_adapter/abstract.py", line 127, in transform
    self.dataframe = self._transform()
  File "/home/lasse/Development/crba-allinone/etl/source_adapter/abstract.py", line 252, in _transform
    self.dataframe = scaler.normalizer(
  File "/home/lasse/Development/crba-allinone/etl/transformation/scaler.py", line 63, in normalizer
    cleansed_data[raw_data_col] = pd.to_numeric(raw_obs_value)
  File "/home/lasse/.cache/pypoetry/virtualenvs/crba-project-5qZtH06h-py3.10/lib/python3.10/site-packages/pandas/core/tools/numeric.py", line 185, in to_numeric
    values, _ = lib.maybe_convert_numeric(
  File "pandas/_libs/lib.pyx", line 2411, in pandas._libs.lib.maybe_convert_numeric
ValueError: Unable to parse string "VALUE WITHOUT MAPPING - PLEASE MAP" at position 0

The above exception was the direct cause of the following exception:

Traceback (most recent call last):
  File "/home/lasse/Development/crba-allinone/etl/run.py", line 44, in build_combined_normalized_csv
    extractor.build()
  File "/home/lasse/Development/crba-allinone/etl/source_adapter/abstract.py", line 100, in build
    raise ExtractionError(
etl.source_adapter.abstract.ExtractionError: Source S-122 failed to extract cause of: Unable to parse string "VALUE WITHOUT MAPPING - PLEASE MAP" at position 0
2023-05-23 23:04:45,062 INFO build_combined_normalized_csv(47) Source S-123 extract with 195 rows::: HumanEnteredBlueprintIndicatorBuilder
2023-05-23 23:04:45,247 INFO build_combined_normalized_csv(47) Source S-124 extract with 195 rows::: UnTreaties
2023-05-23 23:04:45,416 INFO build_combined_normalized_csv(47) Source S-125 extract with 195 rows::: UnTreaties
2023-05-23 23:04:45,591 INFO build_combined_normalized_csv(47) Source S-126 extract with 195 rows::: UnTreaties
2023-05-23 23:04:45,773 INFO build_combined_normalized_csv(47) Source S-127 extract with 195 rows::: UnTreaties
2023-05-23 23:04:45,886 INFO build_combined_normalized_csv(47) Source S-128 extract with 195 rows::: UnTreaties
2023-05-23 23:04:45,955 INFO build_combined_normalized_csv(47) Source S-137 extract with 195 rows::: EITIIndicatorBuilder
2023-05-23 23:04:45,960 WARNING build_combined_normalized_csv(54) Source S-140 failed to extract cause of: 'Year'
Traceback (most recent call last):
  File "/home/lasse/Development/crba-allinone/etl/source_adapter/abstract.py", line 90, in build
    self.download().transform()
  File "/home/lasse/Development/crba-allinone/etl/source_adapter/abstract.py", line 109, in download
    self.dataframe = self._download()
  File "/home/lasse/Development/crba-allinone/etl/source_adapter/who.py", line 54, in _download
    s_157 = self.config.un_pop_tot.merge(
  File "/home/lasse/.cache/pypoetry/virtualenvs/crba-project-5qZtH06h-py3.10/lib/python3.10/site-packages/pandas/core/frame.py", line 10093, in merge
    return merge(
  File "/home/lasse/.cache/pypoetry/virtualenvs/crba-project-5qZtH06h-py3.10/lib/python3.10/site-packages/pandas/core/reshape/merge.py", line 110, in merge
    op = _MergeOperation(
  File "/home/lasse/.cache/pypoetry/virtualenvs/crba-project-5qZtH06h-py3.10/lib/python3.10/site-packages/pandas/core/reshape/merge.py", line 703, in __init__
    ) = self._get_merge_keys()
  File "/home/lasse/.cache/pypoetry/virtualenvs/crba-project-5qZtH06h-py3.10/lib/python3.10/site-packages/pandas/core/reshape/merge.py", line 1162, in _get_merge_keys
    right_keys.append(right._get_label_or_level_values(rk))
  File "/home/lasse/.cache/pypoetry/virtualenvs/crba-project-5qZtH06h-py3.10/lib/python3.10/site-packages/pandas/core/generic.py", line 1850, in _get_label_or_level_values
    raise KeyError(key)
KeyError: 'Year'

The above exception was the direct cause of the following exception:

Traceback (most recent call last):
  File "/home/lasse/Development/crba-allinone/etl/run.py", line 44, in build_combined_normalized_csv
    extractor.build()
  File "/home/lasse/Development/crba-allinone/etl/source_adapter/abstract.py", line 100, in build
    raise ExtractionError(
etl.source_adapter.abstract.ExtractionError: Source S-140 failed to extract cause of: 'Year'
2023-05-23 23:04:46,177 INFO build_combined_normalized_csv(47) Source S-141 extract with 941 rows::: DefaultCSVExtractor
2023-05-23 23:04:46,281 INFO build_combined_normalized_csv(47) Source S-143 extract with 196 rows::: DefaultJsonExtractor
2023-05-23 23:04:46,414 INFO build_combined_normalized_csv(47) Source S-144 extract with 195 rows::: DefaultJsonExtractor
2023-05-23 23:04:46,709 INFO build_combined_normalized_csv(47) Source S-145 extract with 195 rows::: UnTreaties
2023-05-23 23:04:46,831 INFO build_combined_normalized_csv(47) Source S-147 extract with 195 rows::: HumanEnteredBlueprintIndicatorBuilder
2023-05-23 23:04:46,971 WARNING create_log_report_delete_duplicates(771) WARNING: There are 8 duplicate rows in the cleansed dataframe. Apart from soure S-166, this should not be the case. Check if you have mapped all columns (specifically the dimensions) and values. Now dropping duplicate rows and returning dataframe without duplicates.
2023-05-23 23:04:46,999 INFO build_combined_normalized_csv(47) Source S-149 extract with 195 rows::: DefaultJsonExtractor
2023-05-23 23:04:47,650 INFO build_combined_normalized_csv(47) Source S-151 extract with 195 rows::: ICRC_Treaties
2023-05-23 23:04:48,243 INFO build_combined_normalized_csv(47) Source S-152 extract with 195 rows::: ICRC_Treaties
2023-05-23 23:04:48,935 INFO build_combined_normalized_csv(47) Source S-153 extract with 195 rows::: ICRC_Treaties
2023-05-23 23:04:49,043 INFO build_combined_normalized_csv(47) Source S-154 extract with 195 rows::: UnTreaties
2023-05-23 23:04:49,183 INFO build_combined_normalized_csv(47) Source S-155 extract with 195 rows::: HumanEnteredBlueprintIndicatorBuilder
2023-05-23 23:04:49,436 INFO build_combined_normalized_csv(47) Source S-156 extract with 195 rows::: UnTreaties
2023-05-23 23:04:52,935 INFO build_combined_normalized_csv(47) Source S-157 extract with 195 rows::: ILO_Extractor
2023-05-23 23:04:53,076 INFO build_combined_normalized_csv(47) Source S-160 extract with 195 rows::: HumanEnteredBlueprintIndicatorBuilder
2023-05-23 23:04:53,186 INFO build_combined_normalized_csv(47) Source S-220 extract with 195 rows::: HumanEnteredBlueprintIndicatorBuilder
2023-05-23 23:04:54,800 INFO build_combined_normalized_csv(47) Source S-163 extract with 195 rows::: IDMC_Extractor
2023-05-23 23:04:54,921 INFO build_combined_normalized_csv(47) Source S-164 extract with 195 rows::: UnTreaties
2023-05-23 23:04:55,095 INFO build_combined_normalized_csv(47) Source S-165 extract with 417 rows::: DefaultJsonExtractor
2023-05-23 23:04:55,449 INFO build_combined_normalized_csv(47) Source S-166 extract with 509 rows::: DefaultJsonExtractor
2023-05-23 23:04:55,751 INFO build_combined_normalized_csv(47) Source S-167 extract with 399 rows::: UN_SDG_UN_POP
2023-05-23 23:04:55,881 INFO build_combined_normalized_csv(47) Source S-168 extract with 195 rows::: UN_SDG_UN_POP
2023-05-23 23:04:56,021 INFO build_combined_normalized_csv(47) Source S-169 extract with 195 rows::: UN_SDG_UN_POP
2023-05-23 23:04:56,213 INFO build_combined_normalized_csv(47) Source S-170 extract with 195 rows::: UN_SDG_UN_POP
2023-05-23 23:04:57,290 INFO build_combined_normalized_csv(47) Source S-171 extract with 195 rows::: IDMC_Extractor
2023-05-23 23:04:59,506 INFO build_combined_normalized_csv(47) Source S-172 extract with 195 rows::: Inform_Risk_Index_Data
2023-05-23 23:04:59,831 INFO build_combined_normalized_csv(47) Source S-173 extract with 195 rows::: UnTreaties
2023-05-23 23:04:59,952 INFO build_combined_normalized_csv(47) Source S-174 extract with 195 rows::: UnTreaties
2023-05-23 23:05:00,207 INFO build_combined_normalized_csv(47) Source S-175 extract with 195 rows::: CRIN_Treaties
2023-05-23 23:05:00,419 INFO build_combined_normalized_csv(47) Source S-180 extract with 195 rows::: DefaultJsonExtractor
2023-05-23 23:05:00,518 INFO build_combined_normalized_csv(47) Source S-181 extract with 195 rows::: DefaultCSVExtractor
2023-05-23 23:05:02,760 INFO build_combined_normalized_csv(47) Source S-184 extract with 1259 rows::: DefaultJsonExtractor
2023-05-23 23:05:02,842 INFO build_combined_normalized_csv(47) Source S-186 extract with 579 rows::: DefaultCSVExtractor
2023-05-23 23:05:02,988 INFO build_combined_normalized_csv(47) Source S-187 extract with 363 rows::: DefaultCSVExtractor
2023-05-23 23:05:03,070 INFO build_combined_normalized_csv(47) Source S-188 extract with 579 rows::: DefaultCSVExtractor
2023-05-23 23:05:03,123 INFO build_combined_normalized_csv(47) Source S-189 extract with 579 rows::: DefaultCSVExtractor
2023-05-23 23:05:03,124 WARNING build_combined_normalized_csv(54) Source S-192 failed to extract cause of: [Errno 2] No such file or directory: 'config/2023/in/data/staging/S-192.xlsx'
Traceback (most recent call last):
  File "/home/lasse/Development/crba-allinone/etl/source_adapter/abstract.py", line 90, in build
    self.download().transform()
  File "/home/lasse/Development/crba-allinone/etl/source_adapter/abstract.py", line 109, in download
    self.dataframe = self._download()
  File "/home/lasse/Development/crba-allinone/etl/source_adapter/manual.py", line 28, in _download
    self.dataframe = pd.read_excel(
  File "/home/lasse/.cache/pypoetry/virtualenvs/crba-project-5qZtH06h-py3.10/lib/python3.10/site-packages/pandas/util/_decorators.py", line 211, in wrapper
    return func(*args, **kwargs)
  File "/home/lasse/.cache/pypoetry/virtualenvs/crba-project-5qZtH06h-py3.10/lib/python3.10/site-packages/pandas/util/_decorators.py", line 331, in wrapper
    return func(*args, **kwargs)
  File "/home/lasse/.cache/pypoetry/virtualenvs/crba-project-5qZtH06h-py3.10/lib/python3.10/site-packages/pandas/io/excel/_base.py", line 482, in read_excel
    io = ExcelFile(io, storage_options=storage_options, engine=engine)
  File "/home/lasse/.cache/pypoetry/virtualenvs/crba-project-5qZtH06h-py3.10/lib/python3.10/site-packages/pandas/io/excel/_base.py", line 1652, in __init__
    ext = inspect_excel_format(
  File "/home/lasse/.cache/pypoetry/virtualenvs/crba-project-5qZtH06h-py3.10/lib/python3.10/site-packages/pandas/io/excel/_base.py", line 1525, in inspect_excel_format
    with get_handle(
  File "/home/lasse/.cache/pypoetry/virtualenvs/crba-project-5qZtH06h-py3.10/lib/python3.10/site-packages/pandas/io/common.py", line 865, in get_handle
    handle = open(handle, ioargs.mode)
FileNotFoundError: [Errno 2] No such file or directory: 'config/2023/in/data/staging/S-192.xlsx'

The above exception was the direct cause of the following exception:

Traceback (most recent call last):
  File "/home/lasse/Development/crba-allinone/etl/run.py", line 44, in build_combined_normalized_csv
    extractor.build()
  File "/home/lasse/Development/crba-allinone/etl/source_adapter/abstract.py", line 100, in build
    raise ExtractionError(
etl.source_adapter.abstract.ExtractionError: Source S-192 failed to extract cause of: [Errno 2] No such file or directory: 'config/2023/in/data/staging/S-192.xlsx'
2023-05-23 23:05:03,313 WARNING create_log_report_delete_duplicates(771) WARNING: There are 54 duplicate rows in the cleansed dataframe. Apart from soure S-166, this should not be the case. Check if you have mapped all columns (specifically the dimensions) and values. Now dropping duplicate rows and returning dataframe without duplicates.
2023-05-23 23:05:03,338 INFO build_combined_normalized_csv(47) Source S-193 extract with 195 rows::: DefaultJsonExtractor
2023-05-23 23:05:04,424 INFO build_combined_normalized_csv(47) Source S-194 extract with 4945 rows::: DefaultCSVExtractor
2023-05-23 23:05:04,516 INFO build_combined_normalized_csv(47) Source S-196 extract with 195 rows::: DefaultJsonExtractor
2023-05-23 23:05:04,589 INFO build_combined_normalized_csv(47) Source S-197 extract with 195 rows::: DefaultJsonExtractor
2023-05-23 23:05:04,742 INFO build_combined_normalized_csv(47) Source S-198 extract with 195 rows::: DefaultJsonExtractor
2023-05-23 23:05:04,922 INFO build_combined_normalized_csv(47) Source S-199 extract with 195 rows::: DefaultJsonExtractor
2023-05-23 23:05:05,978 INFO build_combined_normalized_csv(47) Source S-200 extract with 3187 rows::: DefaultCSVExtractor
2023-05-23 23:05:06,372 INFO build_combined_normalized_csv(47) Source S-201 extract with 445 rows::: DefaultJsonExtractor
2023-05-23 23:05:06,632 INFO build_combined_normalized_csv(47) Source S-202 extract with 195 rows::: DefaultJsonExtractor
2023-05-23 23:05:06,714 INFO build_combined_normalized_csv(47) Source S-203 extract with 196 rows::: DefaultJsonExtractor
2023-05-23 23:05:06,824 INFO build_combined_normalized_csv(47) Source S-204 extract with 196 rows::: DefaultJsonExtractor
2023-05-23 23:05:07,008 INFO build_combined_normalized_csv(47) Source S-205 extract with 195 rows::: DefaultJsonExtractor
2023-05-23 23:05:07,210 INFO build_combined_normalized_csv(47) Source S-206 extract with 453 rows::: DefaultJsonExtractor
2023-05-23 23:05:07,321 INFO build_combined_normalized_csv(47) Source S-207 extract with 195 rows::: HumanEnteredBlueprintIndicatorBuilder
2023-05-23 23:05:08,451 INFO build_combined_normalized_csv(47) Source S-209 extract with 195 rows::: IDMC_Extractor
2023-05-23 23:05:08,579 INFO build_combined_normalized_csv(47) Source S-213 extract with 195 rows::: HumanEnteredBlueprintIndicatorBuilder
2023-05-23 23:05:08,691 INFO build_combined_normalized_csv(47) Source S-215 extract with 195 rows::: HumanEnteredBlueprintIndicatorBuilder
2023-05-23 23:05:08,807 INFO build_combined_normalized_csv(47) Source S-216 extract with 195 rows::: HumanEnteredBlueprintIndicatorBuilder
2023-05-23 23:05:08,920 INFO build_combined_normalized_csv(47) Source S-217 extract with 195 rows::: HumanEnteredBlueprintIndicatorBuilder
2023-05-23 23:05:09,355 INFO build_combined_normalized_csv(47) Source S-218 extract with 195 rows::: DefaultJsonExtractor
2023-05-23 23:05:09,431 INFO build_combined_normalized_csv(47) Source S-8 extract with 195 rows::: WPA_Extractor
2023-05-23 23:05:09,505 INFO build_combined_normalized_csv(47) Source S-9 extract with 195 rows::: WPA_Extractor
2023-05-23 23:05:09,885 INFO build_combined_normalized_csv(47) Source S-10 extract with 195 rows::: WPA_Extractor
2023-05-23 23:05:10,308 WARNING build_combined_normalized_csv(54) Source S-11 failed to extract cause of: '[None] not in index'
Traceback (most recent call last):
  File "/home/lasse/Development/crba-allinone/etl/source_adapter/abstract.py", line 90, in build
    self.download().transform()
  File "/home/lasse/Development/crba-allinone/etl/source_adapter/abstract.py", line 109, in download
    self.dataframe = self._download()
  File "/home/lasse/Development/crba-allinone/etl/source_adapter/manual.py", line 113, in _download
    self.dataframe = self.dataframe.loc[
  File "/home/lasse/.cache/pypoetry/virtualenvs/crba-project-5qZtH06h-py3.10/lib/python3.10/site-packages/pandas/core/indexing.py", line 1067, in __getitem__
    return self._getitem_tuple(key)
  File "/home/lasse/.cache/pypoetry/virtualenvs/crba-project-5qZtH06h-py3.10/lib/python3.10/site-packages/pandas/core/indexing.py", line 1256, in _getitem_tuple
    return self._getitem_tuple_same_dim(tup)
  File "/home/lasse/.cache/pypoetry/virtualenvs/crba-project-5qZtH06h-py3.10/lib/python3.10/site-packages/pandas/core/indexing.py", line 924, in _getitem_tuple_same_dim
    retval = getattr(retval, self.name)._getitem_axis(key, axis=i)
  File "/home/lasse/.cache/pypoetry/virtualenvs/crba-project-5qZtH06h-py3.10/lib/python3.10/site-packages/pandas/core/indexing.py", line 1301, in _getitem_axis
    return self._getitem_iterable(key, axis=axis)
  File "/home/lasse/.cache/pypoetry/virtualenvs/crba-project-5qZtH06h-py3.10/lib/python3.10/site-packages/pandas/core/indexing.py", line 1239, in _getitem_iterable
    keyarr, indexer = self._get_listlike_indexer(key, axis)
  File "/home/lasse/.cache/pypoetry/virtualenvs/crba-project-5qZtH06h-py3.10/lib/python3.10/site-packages/pandas/core/indexing.py", line 1432, in _get_listlike_indexer
    keyarr, indexer = ax._get_indexer_strict(key, axis_name)
  File "/home/lasse/.cache/pypoetry/virtualenvs/crba-project-5qZtH06h-py3.10/lib/python3.10/site-packages/pandas/core/indexes/base.py", line 6070, in _get_indexer_strict
    self._raise_if_missing(keyarr, indexer, axis_name)
  File "/home/lasse/.cache/pypoetry/virtualenvs/crba-project-5qZtH06h-py3.10/lib/python3.10/site-packages/pandas/core/indexes/base.py", line 6133, in _raise_if_missing
    raise KeyError(f"{not_found} not in index")
KeyError: '[None] not in index'

The above exception was the direct cause of the following exception:

Traceback (most recent call last):
  File "/home/lasse/Development/crba-allinone/etl/run.py", line 44, in build_combined_normalized_csv
    extractor.build()
  File "/home/lasse/Development/crba-allinone/etl/source_adapter/abstract.py", line 100, in build
    raise ExtractionError(
etl.source_adapter.abstract.ExtractionError: Source S-11 failed to extract cause of: '[None] not in index'
2023-05-23 23:05:10,669 INFO build_combined_normalized_csv(47) Source S-13 extract with 195 rows::: WPA_Extractor
2023-05-23 23:05:11,096 INFO build_combined_normalized_csv(47) Source S-29 extract with 195 rows::: WPA_Extractor
2023-05-23 23:05:11,182 INFO build_combined_normalized_csv(47) Source S-33 extract with 195 rows::: WPA_Extractor
2023-05-23 23:05:11,236 INFO build_combined_normalized_csv(47) Source S-34 extract with 195 rows::: WPA_Extractor
2023-05-23 23:05:11,338 WARNING build_combined_normalized_csv(54) Source S-35 failed to extract cause of: 'RAW_OBS_VALUE'
Traceback (most recent call last):
  File "/home/lasse/.cache/pypoetry/virtualenvs/crba-project-5qZtH06h-py3.10/lib/python3.10/site-packages/pandas/core/indexes/base.py", line 3802, in get_loc
    return self._engine.get_loc(casted_key)
  File "pandas/_libs/index.pyx", line 138, in pandas._libs.index.IndexEngine.get_loc
  File "pandas/_libs/index.pyx", line 165, in pandas._libs.index.IndexEngine.get_loc
  File "pandas/_libs/hashtable_class_helper.pxi", line 5745, in pandas._libs.hashtable.PyObjectHashTable.get_item
  File "pandas/_libs/hashtable_class_helper.pxi", line 5753, in pandas._libs.hashtable.PyObjectHashTable.get_item
KeyError: 'RAW_OBS_VALUE'

The above exception was the direct cause of the following exception:

Traceback (most recent call last):
  File "/home/lasse/Development/crba-allinone/etl/source_adapter/abstract.py", line 90, in build
    self.download().transform()
  File "/home/lasse/Development/crba-allinone/etl/source_adapter/abstract.py", line 127, in transform
    self.dataframe = self._transform()
  File "/home/lasse/Development/crba-allinone/etl/source_adapter/wpa.py", line 121, in _transform
    self.dataframe_cleansed = cleanse.encode_categorical_variables(
  File "/home/lasse/Development/crba-allinone/etl/transformation/cleanse.py", line 702, in encode_categorical_variables
    dataframe[obs_raw_value_source].astype(
  File "/home/lasse/.cache/pypoetry/virtualenvs/crba-project-5qZtH06h-py3.10/lib/python3.10/site-packages/pandas/core/frame.py", line 3807, in __getitem__
    indexer = self.columns.get_loc(key)
  File "/home/lasse/.cache/pypoetry/virtualenvs/crba-project-5qZtH06h-py3.10/lib/python3.10/site-packages/pandas/core/indexes/base.py", line 3804, in get_loc
    raise KeyError(key) from err
KeyError: 'RAW_OBS_VALUE'

The above exception was the direct cause of the following exception:

Traceback (most recent call last):
  File "/home/lasse/Development/crba-allinone/etl/run.py", line 44, in build_combined_normalized_csv
    extractor.build()
  File "/home/lasse/Development/crba-allinone/etl/source_adapter/abstract.py", line 100, in build
    raise ExtractionError(
etl.source_adapter.abstract.ExtractionError: Source S-35 failed to extract cause of: 'RAW_OBS_VALUE'
2023-05-23 23:05:11,440 WARNING build_combined_normalized_csv(54) Source S-36 failed to extract cause of: 'RAW_OBS_VALUE'
Traceback (most recent call last):
  File "/home/lasse/.cache/pypoetry/virtualenvs/crba-project-5qZtH06h-py3.10/lib/python3.10/site-packages/pandas/core/indexes/base.py", line 3802, in get_loc
    return self._engine.get_loc(casted_key)
  File "pandas/_libs/index.pyx", line 138, in pandas._libs.index.IndexEngine.get_loc
  File "pandas/_libs/index.pyx", line 165, in pandas._libs.index.IndexEngine.get_loc
  File "pandas/_libs/hashtable_class_helper.pxi", line 5745, in pandas._libs.hashtable.PyObjectHashTable.get_item
  File "pandas/_libs/hashtable_class_helper.pxi", line 5753, in pandas._libs.hashtable.PyObjectHashTable.get_item
KeyError: 'RAW_OBS_VALUE'

The above exception was the direct cause of the following exception:

Traceback (most recent call last):
  File "/home/lasse/Development/crba-allinone/etl/source_adapter/abstract.py", line 90, in build
    self.download().transform()
  File "/home/lasse/Development/crba-allinone/etl/source_adapter/abstract.py", line 127, in transform
    self.dataframe = self._transform()
  File "/home/lasse/Development/crba-allinone/etl/source_adapter/wpa.py", line 121, in _transform
    self.dataframe_cleansed = cleanse.encode_categorical_variables(
  File "/home/lasse/Development/crba-allinone/etl/transformation/cleanse.py", line 702, in encode_categorical_variables
    dataframe[obs_raw_value_source].astype(
  File "/home/lasse/.cache/pypoetry/virtualenvs/crba-project-5qZtH06h-py3.10/lib/python3.10/site-packages/pandas/core/frame.py", line 3807, in __getitem__
    indexer = self.columns.get_loc(key)
  File "/home/lasse/.cache/pypoetry/virtualenvs/crba-project-5qZtH06h-py3.10/lib/python3.10/site-packages/pandas/core/indexes/base.py", line 3804, in get_loc
    raise KeyError(key) from err
KeyError: 'RAW_OBS_VALUE'

The above exception was the direct cause of the following exception:

Traceback (most recent call last):
  File "/home/lasse/Development/crba-allinone/etl/run.py", line 44, in build_combined_normalized_csv
    extractor.build()
  File "/home/lasse/Development/crba-allinone/etl/source_adapter/abstract.py", line 100, in build
    raise ExtractionError(
etl.source_adapter.abstract.ExtractionError: Source S-36 failed to extract cause of: 'RAW_OBS_VALUE'
2023-05-23 23:05:11,506 WARNING build_combined_normalized_csv(54) Source S-37 failed to extract cause of: "['sh_covered'] not in index"
Traceback (most recent call last):
  File "/home/lasse/Development/crba-allinone/etl/source_adapter/abstract.py", line 90, in build
    self.download().transform()
  File "/home/lasse/Development/crba-allinone/etl/source_adapter/abstract.py", line 109, in download
    self.dataframe = self._download()
  File "/home/lasse/Development/crba-allinone/etl/source_adapter/wpa.py", line 27, in _download
    self.dataframe = self.dataframe[['iso3', self.wpa_obs_raw_col]]
  File "/home/lasse/.cache/pypoetry/virtualenvs/crba-project-5qZtH06h-py3.10/lib/python3.10/site-packages/pandas/core/frame.py", line 3813, in __getitem__
    indexer = self.columns._get_indexer_strict(key, "columns")[1]
  File "/home/lasse/.cache/pypoetry/virtualenvs/crba-project-5qZtH06h-py3.10/lib/python3.10/site-packages/pandas/core/indexes/base.py", line 6070, in _get_indexer_strict
    self._raise_if_missing(keyarr, indexer, axis_name)
  File "/home/lasse/.cache/pypoetry/virtualenvs/crba-project-5qZtH06h-py3.10/lib/python3.10/site-packages/pandas/core/indexes/base.py", line 6133, in _raise_if_missing
    raise KeyError(f"{not_found} not in index")
KeyError: "['sh_covered'] not in index"

The above exception was the direct cause of the following exception:

Traceback (most recent call last):
  File "/home/lasse/Development/crba-allinone/etl/run.py", line 44, in build_combined_normalized_csv
    extractor.build()
  File "/home/lasse/Development/crba-allinone/etl/source_adapter/abstract.py", line 100, in build
    raise ExtractionError(
etl.source_adapter.abstract.ExtractionError: Source S-37 failed to extract cause of: "['sh_covered'] not in index"
2023-05-23 23:05:11,863 INFO build_combined_normalized_csv(47) Source S-38 extract with 195 rows::: WPA_Extractor
2023-05-23 23:05:12,251 INFO build_combined_normalized_csv(47) Source S-40 extract with 195 rows::: WPA_Extractor
2023-05-23 23:05:12,511 INFO build_combined_normalized_csv(47) Source S-51 extract with 195 rows::: Global_Slavery_Index
2023-05-23 23:05:12,595 INFO build_combined_normalized_csv(47) Source S-54 extract with 195 rows::: WPA_Extractor
2023-05-23 23:05:12,676 INFO build_combined_normalized_csv(47) Source S-55 extract with 195 rows::: WPA_Extractor
2023-05-23 23:05:12,761 INFO build_combined_normalized_csv(47) Source S-56 extract with 195 rows::: WPA_Extractor
2023-05-23 23:05:12,843 INFO build_combined_normalized_csv(47) Source S-57 extract with 195 rows::: WPA_Extractor
2023-05-23 23:05:12,927 INFO build_combined_normalized_csv(47) Source S-58 extract with 195 rows::: WPA_Extractor
2023-05-23 23:05:13,011 INFO build_combined_normalized_csv(47) Source S-59 extract with 195 rows::: WPA_Extractor
2023-05-23 23:05:13,130 INFO build_combined_normalized_csv(47) Source S-60 extract with 195 rows::: HumanEnteredBlueprintIndicatorBuilder
2023-05-23 23:05:13,248 INFO build_combined_normalized_csv(47) Source S-61 extract with 195 rows::: HumanEnteredBlueprintIndicatorBuilder
2023-05-23 23:05:13,388 INFO build_combined_normalized_csv(47) Source S-73 extract with 195 rows::: HumanEnteredBlueprintIndicatorBuilder
2023-05-23 23:05:13,521 INFO build_combined_normalized_csv(47) Source S-75 extract with 195 rows::: FCTC_Data
2023-05-23 23:05:13,634 INFO build_combined_normalized_csv(47) Source S-94 extract with 195 rows::: HumanEnteredBlueprintIndicatorBuilder
2023-05-23 23:05:13,746 INFO build_combined_normalized_csv(47) Source S-95 extract with 195 rows::: HumanEnteredBlueprintIndicatorBuilder
2023-05-23 23:05:13,862 INFO build_combined_normalized_csv(47) Source S-96 extract with 195 rows::: HumanEnteredBlueprintIndicatorBuilder
2023-05-23 23:05:14,278 WARNING build_combined_normalized_csv(54) Source S-97 failed to extract cause of: '[None] not in index'
Traceback (most recent call last):
  File "/home/lasse/Development/crba-allinone/etl/source_adapter/abstract.py", line 90, in build
    self.download().transform()
  File "/home/lasse/Development/crba-allinone/etl/source_adapter/abstract.py", line 109, in download
    self.dataframe = self._download()
  File "/home/lasse/Development/crba-allinone/etl/source_adapter/manual.py", line 113, in _download
    self.dataframe = self.dataframe.loc[
  File "/home/lasse/.cache/pypoetry/virtualenvs/crba-project-5qZtH06h-py3.10/lib/python3.10/site-packages/pandas/core/indexing.py", line 1067, in __getitem__
    return self._getitem_tuple(key)
  File "/home/lasse/.cache/pypoetry/virtualenvs/crba-project-5qZtH06h-py3.10/lib/python3.10/site-packages/pandas/core/indexing.py", line 1256, in _getitem_tuple
    return self._getitem_tuple_same_dim(tup)
  File "/home/lasse/.cache/pypoetry/virtualenvs/crba-project-5qZtH06h-py3.10/lib/python3.10/site-packages/pandas/core/indexing.py", line 924, in _getitem_tuple_same_dim
    retval = getattr(retval, self.name)._getitem_axis(key, axis=i)
  File "/home/lasse/.cache/pypoetry/virtualenvs/crba-project-5qZtH06h-py3.10/lib/python3.10/site-packages/pandas/core/indexing.py", line 1301, in _getitem_axis
    return self._getitem_iterable(key, axis=axis)
  File "/home/lasse/.cache/pypoetry/virtualenvs/crba-project-5qZtH06h-py3.10/lib/python3.10/site-packages/pandas/core/indexing.py", line 1239, in _getitem_iterable
    keyarr, indexer = self._get_listlike_indexer(key, axis)
  File "/home/lasse/.cache/pypoetry/virtualenvs/crba-project-5qZtH06h-py3.10/lib/python3.10/site-packages/pandas/core/indexing.py", line 1432, in _get_listlike_indexer
    keyarr, indexer = ax._get_indexer_strict(key, axis_name)
  File "/home/lasse/.cache/pypoetry/virtualenvs/crba-project-5qZtH06h-py3.10/lib/python3.10/site-packages/pandas/core/indexes/base.py", line 6070, in _get_indexer_strict
    self._raise_if_missing(keyarr, indexer, axis_name)
  File "/home/lasse/.cache/pypoetry/virtualenvs/crba-project-5qZtH06h-py3.10/lib/python3.10/site-packages/pandas/core/indexes/base.py", line 6133, in _raise_if_missing
    raise KeyError(f"{not_found} not in index")
KeyError: '[None] not in index'

The above exception was the direct cause of the following exception:

Traceback (most recent call last):
  File "/home/lasse/Development/crba-allinone/etl/run.py", line 44, in build_combined_normalized_csv
    extractor.build()
  File "/home/lasse/Development/crba-allinone/etl/source_adapter/abstract.py", line 100, in build
    raise ExtractionError(
etl.source_adapter.abstract.ExtractionError: Source S-97 failed to extract cause of: '[None] not in index'
2023-05-23 23:05:14,595 WARNING build_combined_normalized_csv(54) Source S-101 failed to extract cause of: '[None] not in index'
Traceback (most recent call last):
  File "/home/lasse/Development/crba-allinone/etl/source_adapter/abstract.py", line 90, in build
    self.download().transform()
  File "/home/lasse/Development/crba-allinone/etl/source_adapter/abstract.py", line 109, in download
    self.dataframe = self._download()
  File "/home/lasse/Development/crba-allinone/etl/source_adapter/manual.py", line 113, in _download
    self.dataframe = self.dataframe.loc[
  File "/home/lasse/.cache/pypoetry/virtualenvs/crba-project-5qZtH06h-py3.10/lib/python3.10/site-packages/pandas/core/indexing.py", line 1067, in __getitem__
    return self._getitem_tuple(key)
  File "/home/lasse/.cache/pypoetry/virtualenvs/crba-project-5qZtH06h-py3.10/lib/python3.10/site-packages/pandas/core/indexing.py", line 1256, in _getitem_tuple
    return self._getitem_tuple_same_dim(tup)
  File "/home/lasse/.cache/pypoetry/virtualenvs/crba-project-5qZtH06h-py3.10/lib/python3.10/site-packages/pandas/core/indexing.py", line 924, in _getitem_tuple_same_dim
    retval = getattr(retval, self.name)._getitem_axis(key, axis=i)
  File "/home/lasse/.cache/pypoetry/virtualenvs/crba-project-5qZtH06h-py3.10/lib/python3.10/site-packages/pandas/core/indexing.py", line 1301, in _getitem_axis
    return self._getitem_iterable(key, axis=axis)
  File "/home/lasse/.cache/pypoetry/virtualenvs/crba-project-5qZtH06h-py3.10/lib/python3.10/site-packages/pandas/core/indexing.py", line 1239, in _getitem_iterable
    keyarr, indexer = self._get_listlike_indexer(key, axis)
  File "/home/lasse/.cache/pypoetry/virtualenvs/crba-project-5qZtH06h-py3.10/lib/python3.10/site-packages/pandas/core/indexing.py", line 1432, in _get_listlike_indexer
    keyarr, indexer = ax._get_indexer_strict(key, axis_name)
  File "/home/lasse/.cache/pypoetry/virtualenvs/crba-project-5qZtH06h-py3.10/lib/python3.10/site-packages/pandas/core/indexes/base.py", line 6070, in _get_indexer_strict
    self._raise_if_missing(keyarr, indexer, axis_name)
  File "/home/lasse/.cache/pypoetry/virtualenvs/crba-project-5qZtH06h-py3.10/lib/python3.10/site-packages/pandas/core/indexes/base.py", line 6133, in _raise_if_missing
    raise KeyError(f"{not_found} not in index")
KeyError: '[None] not in index'

The above exception was the direct cause of the following exception:

Traceback (most recent call last):
  File "/home/lasse/Development/crba-allinone/etl/run.py", line 44, in build_combined_normalized_csv
    extractor.build()
  File "/home/lasse/Development/crba-allinone/etl/source_adapter/abstract.py", line 100, in build
    raise ExtractionError(
etl.source_adapter.abstract.ExtractionError: Source S-101 failed to extract cause of: '[None] not in index'
2023-05-23 23:05:14,708 INFO build_combined_normalized_csv(47) Source S-105 extract with 195 rows::: KidsRightsIndex
2023-05-23 23:05:14,815 INFO build_combined_normalized_csv(47) Source S-106 extract with 195 rows::: KidsRightsIndex
2023-05-23 23:05:14,951 INFO build_combined_normalized_csv(47) Source S-107 extract with 195 rows::: KidsRightsIndex
2023-05-23 23:05:15,371 WARNING build_combined_normalized_csv(54) Source S-117 failed to extract cause of: '[None] not in index'
Traceback (most recent call last):
  File "/home/lasse/Development/crba-allinone/etl/source_adapter/abstract.py", line 90, in build
    self.download().transform()
  File "/home/lasse/Development/crba-allinone/etl/source_adapter/abstract.py", line 109, in download
    self.dataframe = self._download()
  File "/home/lasse/Development/crba-allinone/etl/source_adapter/manual.py", line 113, in _download
    self.dataframe = self.dataframe.loc[
  File "/home/lasse/.cache/pypoetry/virtualenvs/crba-project-5qZtH06h-py3.10/lib/python3.10/site-packages/pandas/core/indexing.py", line 1067, in __getitem__
    return self._getitem_tuple(key)
  File "/home/lasse/.cache/pypoetry/virtualenvs/crba-project-5qZtH06h-py3.10/lib/python3.10/site-packages/pandas/core/indexing.py", line 1256, in _getitem_tuple
    return self._getitem_tuple_same_dim(tup)
  File "/home/lasse/.cache/pypoetry/virtualenvs/crba-project-5qZtH06h-py3.10/lib/python3.10/site-packages/pandas/core/indexing.py", line 924, in _getitem_tuple_same_dim
    retval = getattr(retval, self.name)._getitem_axis(key, axis=i)
  File "/home/lasse/.cache/pypoetry/virtualenvs/crba-project-5qZtH06h-py3.10/lib/python3.10/site-packages/pandas/core/indexing.py", line 1301, in _getitem_axis
    return self._getitem_iterable(key, axis=axis)
  File "/home/lasse/.cache/pypoetry/virtualenvs/crba-project-5qZtH06h-py3.10/lib/python3.10/site-packages/pandas/core/indexing.py", line 1239, in _getitem_iterable
    keyarr, indexer = self._get_listlike_indexer(key, axis)
  File "/home/lasse/.cache/pypoetry/virtualenvs/crba-project-5qZtH06h-py3.10/lib/python3.10/site-packages/pandas/core/indexing.py", line 1432, in _get_listlike_indexer
    keyarr, indexer = ax._get_indexer_strict(key, axis_name)
  File "/home/lasse/.cache/pypoetry/virtualenvs/crba-project-5qZtH06h-py3.10/lib/python3.10/site-packages/pandas/core/indexes/base.py", line 6070, in _get_indexer_strict
    self._raise_if_missing(keyarr, indexer, axis_name)
  File "/home/lasse/.cache/pypoetry/virtualenvs/crba-project-5qZtH06h-py3.10/lib/python3.10/site-packages/pandas/core/indexes/base.py", line 6133, in _raise_if_missing
    raise KeyError(f"{not_found} not in index")
KeyError: '[None] not in index'

The above exception was the direct cause of the following exception:

Traceback (most recent call last):
  File "/home/lasse/Development/crba-allinone/etl/run.py", line 44, in build_combined_normalized_csv
    extractor.build()
  File "/home/lasse/Development/crba-allinone/etl/source_adapter/abstract.py", line 100, in build
    raise ExtractionError(
etl.source_adapter.abstract.ExtractionError: Source S-117 failed to extract cause of: '[None] not in index'
2023-05-23 23:05:15,419 INFO build_combined_normalized_csv(47) Source S-118 extract with 195 rows::: DefaultCSVExtractor
2023-05-23 23:05:15,528 INFO build_combined_normalized_csv(47) Source S-129 extract with 195 rows::: HumanEnteredBlueprintIndicatorBuilder
2023-05-23 23:05:15,639 INFO build_combined_normalized_csv(47) Source S-131 extract with 195 rows::: HumanEnteredBlueprintIndicatorBuilder
2023-05-23 23:05:15,751 INFO build_combined_normalized_csv(47) Source S-132 extract with 195 rows::: HumanEnteredBlueprintIndicatorBuilder
2023-05-23 23:05:15,862 INFO build_combined_normalized_csv(47) Source S-133 extract with 195 rows::: HumanEnteredBlueprintIndicatorBuilder
2023-05-23 23:05:15,982 INFO build_combined_normalized_csv(47) Source S-134 extract with 195 rows::: HumanEnteredBlueprintIndicatorBuilder
2023-05-23 23:05:16,097 INFO build_combined_normalized_csv(47) Source S-135 extract with 195 rows::: HumanEnteredBlueprintIndicatorBuilder
2023-05-23 23:05:16,158 INFO build_combined_normalized_csv(47) Source S-136 extract with 195 rows::: Climate_Watch_Data_Paris_Contributions
2023-05-23 23:05:16,256 INFO build_combined_normalized_csv(47) Source S-142 extract with 195 rows::: Climate_Watch_Data_S_159
2023-05-23 23:05:16,370 INFO build_combined_normalized_csv(47) Source S-148 extract with 195 rows::: HumanEnteredBlueprintIndicatorBuilder
2023-05-23 23:05:16,479 INFO build_combined_normalized_csv(47) Source S-150 extract with 195 rows::: Landmark_Data
2023-05-23 23:05:16,588 INFO build_combined_normalized_csv(47) Source S-176 extract with 195 rows::: KidsRightsIndex
2023-05-23 23:05:16,722 INFO build_combined_normalized_csv(47) Source S-177 extract with 195 rows::: KidsRightsIndex
2023-05-23 23:05:16,862 INFO build_combined_normalized_csv(47) Source S-178 extract with 195 rows::: KidsRightsIndex
2023-05-23 23:05:16,972 INFO build_combined_normalized_csv(47) Source S-179 extract with 195 rows::: KidsRightsIndex
2023-05-23 23:05:17,402 WARNING build_combined_normalized_csv(54) Source S-208 failed to extract cause of: '[None] not in index'
Traceback (most recent call last):
  File "/home/lasse/Development/crba-allinone/etl/source_adapter/abstract.py", line 90, in build
    self.download().transform()
  File "/home/lasse/Development/crba-allinone/etl/source_adapter/abstract.py", line 109, in download
    self.dataframe = self._download()
  File "/home/lasse/Development/crba-allinone/etl/source_adapter/manual.py", line 113, in _download
    self.dataframe = self.dataframe.loc[
  File "/home/lasse/.cache/pypoetry/virtualenvs/crba-project-5qZtH06h-py3.10/lib/python3.10/site-packages/pandas/core/indexing.py", line 1067, in __getitem__
    return self._getitem_tuple(key)
  File "/home/lasse/.cache/pypoetry/virtualenvs/crba-project-5qZtH06h-py3.10/lib/python3.10/site-packages/pandas/core/indexing.py", line 1256, in _getitem_tuple
    return self._getitem_tuple_same_dim(tup)
  File "/home/lasse/.cache/pypoetry/virtualenvs/crba-project-5qZtH06h-py3.10/lib/python3.10/site-packages/pandas/core/indexing.py", line 924, in _getitem_tuple_same_dim
    retval = getattr(retval, self.name)._getitem_axis(key, axis=i)
  File "/home/lasse/.cache/pypoetry/virtualenvs/crba-project-5qZtH06h-py3.10/lib/python3.10/site-packages/pandas/core/indexing.py", line 1301, in _getitem_axis
    return self._getitem_iterable(key, axis=axis)
  File "/home/lasse/.cache/pypoetry/virtualenvs/crba-project-5qZtH06h-py3.10/lib/python3.10/site-packages/pandas/core/indexing.py", line 1239, in _getitem_iterable
    keyarr, indexer = self._get_listlike_indexer(key, axis)
  File "/home/lasse/.cache/pypoetry/virtualenvs/crba-project-5qZtH06h-py3.10/lib/python3.10/site-packages/pandas/core/indexing.py", line 1432, in _get_listlike_indexer
    keyarr, indexer = ax._get_indexer_strict(key, axis_name)
  File "/home/lasse/.cache/pypoetry/virtualenvs/crba-project-5qZtH06h-py3.10/lib/python3.10/site-packages/pandas/core/indexes/base.py", line 6070, in _get_indexer_strict
    self._raise_if_missing(keyarr, indexer, axis_name)
  File "/home/lasse/.cache/pypoetry/virtualenvs/crba-project-5qZtH06h-py3.10/lib/python3.10/site-packages/pandas/core/indexes/base.py", line 6133, in _raise_if_missing
    raise KeyError(f"{not_found} not in index")
KeyError: '[None] not in index'

The above exception was the direct cause of the following exception:

Traceback (most recent call last):
  File "/home/lasse/Development/crba-allinone/etl/run.py", line 44, in build_combined_normalized_csv
    extractor.build()
  File "/home/lasse/Development/crba-allinone/etl/source_adapter/abstract.py", line 100, in build
    raise ExtractionError(
etl.source_adapter.abstract.ExtractionError: Source S-208 failed to extract cause of: '[None] not in index'
2023-05-23 23:05:17,482 INFO build_combined_normalized_csv(47) Source S-210 extract with 195 rows::: WPA_Extractor
2023-05-23 23:05:17,539 INFO build_combined_normalized_csv(47) Source S-211 extract with 195 rows::: WPA_Extractor
2023-05-23 23:05:17,654 INFO build_combined_normalized_csv(47) Source S-212 extract with 195 rows::: HumanEnteredBlueprintIndicatorBuilder
2023-05-23 23:05:17,746 INFO build_combined_normalized_csv(47) Source S-214 extract with 195 rows::: HumanEnteredBlueprintIndicatorBuilder
2023-05-23 23:05:17,869 INFO build_combined_normalized_csv(47) Source S-12 extract with 195 rows::: HumanEnteredBlueprintIndicatorBuilder
2023-05-23 23:05:18,008 INFO build_combined_normalized_csv(47) Source S-41 extract with 739 rows::: DefaultCSVExtractor
2023-05-23 23:05:18,103 INFO build_combined_normalized_csv(47) Source S-42 extract with 310 rows::: DefaultCSVExtractor
2023-05-23 23:05:18,181 INFO build_combined_normalized_csv(47) Source S-44 extract with 195 rows::: DefaultCSVExtractor
2023-05-23 23:05:18,219 INFO build_combined_normalized_csv(47) Source S-185 extract with 195 rows::: DefaultCSVExtractor
2023-05-23 23:05:18,286 INFO build_combined_normalized_csv(47) Source S-190 extract with 195 rows::: DefaultCSVExtractor
2023-05-23 23:05:18,990 INFO build_combined_normalized_csv(47) Source S-138 extract with 195 rows::: NRGI
2023-05-23 23:05:19,726 INFO build_combined_normalized_csv(47) Source S-139 extract with 195 rows::: NRGI
2023-05-23 23:05:19,841 INFO build_combined_normalized_csv(47) Source S-219 extract with 195 rows::: HumanEnteredBlueprintIndicatorBuilder
2023-05-23 23:05:20,840 INFO build_combined_normalized_csv(47) Source S-162 extract with 195 rows::: IDMC_Extractor
